Looking in links: /cvmfs/soft.computecanada.ca/custom/python/wheelhouse/gentoo2023/x86-64-v3, /cvmfs/soft.computecanada.ca/custom/python/wheelhouse/gentoo2023/generic, /cvmfs/soft.computecanada.ca/custom/python/wheelhouse/generic
Obtaining file:///lustre06/project/6086105/ymbahram/improved-diffusion/improved_diffusion/SDFT
  Preparing metadata (setup.py): started
  Preparing metadata (setup.py): finished with status 'done'
Requirement already satisfied: blobfile>=1.0.5 in /lustre06/project/6086105/ymbahram/gputorch3_10/lib/python3.10/site-packages (from improved-diffusion==0.0.0) (2.1.1+computecanada)
Requirement already satisfied: torch in /lustre06/project/6086105/ymbahram/gputorch3_10/lib/python3.10/site-packages (from improved-diffusion==0.0.0) (2.3.0+computecanada)
Requirement already satisfied: tqdm in /lustre06/project/6086105/ymbahram/gputorch3_10/lib/python3.10/site-packages (from improved-diffusion==0.0.0) (4.66.4+computecanada)
Requirement already satisfied: numpy in /lustre06/project/6086105/ymbahram/gputorch3_10/lib/python3.10/site-packages (from improved-diffusion==0.0.0) (1.26.4+computecanada)
Requirement already satisfied: matplotlib in /lustre06/project/6086105/ymbahram/gputorch3_10/lib/python3.10/site-packages (from improved-diffusion==0.0.0) (3.9.0+computecanada)
WARNING: Retrying (Retry(total=4, connect=None, read=None, redirect=None, status=None)) after connection broken by 'NewConnectionError('<pip._vendor.urllib3.connection.HTTPSConnection object at 0x1551784460e0>: Failed to establish a new connection: [Errno 101] Network is unreachable')': /simple/tensorflow/
WARNING: Retrying (Retry(total=3, connect=None, read=None, redirect=None, status=None)) after connection broken by 'NewConnectionError('<pip._vendor.urllib3.connection.HTTPSConnection object at 0x155178288400>: Failed to establish a new connection: [Errno 101] Network is unreachable')': /simple/tensorflow/
WARNING: Retrying (Retry(total=2, connect=None, read=None, redirect=None, status=None)) after connection broken by 'NewConnectionError('<pip._vendor.urllib3.connection.HTTPSConnection object at 0x155178288610>: Failed to establish a new connection: [Errno 101] Network is unreachable')': /simple/tensorflow/
WARNING: Retrying (Retry(total=1, connect=None, read=None, redirect=None, status=None)) after connection broken by 'NewConnectionError('<pip._vendor.urllib3.connection.HTTPSConnection object at 0x1551782887c0>: Failed to establish a new connection: [Errno 101] Network is unreachable')': /simple/tensorflow/
WARNING: Retrying (Retry(total=0, connect=None, read=None, redirect=None, status=None)) after connection broken by 'NewConnectionError('<pip._vendor.urllib3.connection.HTTPSConnection object at 0x155178288970>: Failed to establish a new connection: [Errno 101] Network is unreachable')': /simple/tensorflow/
Processing /cvmfs/soft.computecanada.ca/custom/python/wheelhouse/gentoo2023/generic/tensorflow-2.17.0+computecanada-cp310-cp310-linux_x86_64.whl
Requirement already satisfied: urllib3<3,>=1.25.3 in /lustre06/project/6086105/ymbahram/gputorch3_10/lib/python3.10/site-packages (from blobfile>=1.0.5->improved-diffusion==0.0.0) (2.2.3+computecanada)
Requirement already satisfied: pycryptodomex~=3.8 in /lustre06/project/6086105/ymbahram/gputorch3_10/lib/python3.10/site-packages (from blobfile>=1.0.5->improved-diffusion==0.0.0) (3.19.0+computecanada)
Requirement already satisfied: lxml~=4.9 in /lustre06/project/6086105/ymbahram/gputorch3_10/lib/python3.10/site-packages (from blobfile>=1.0.5->improved-diffusion==0.0.0) (4.9.2+computecanada)
Requirement already satisfied: filelock~=3.0 in /lustre06/project/6086105/ymbahram/gputorch3_10/lib/python3.10/site-packages (from blobfile>=1.0.5->improved-diffusion==0.0.0) (3.14.0)
Requirement already satisfied: fonttools>=4.22.0 in /lustre06/project/6086105/ymbahram/gputorch3_10/lib/python3.10/site-packages (from matplotlib->improved-diffusion==0.0.0) (4.53.1+computecanada)
Requirement already satisfied: contourpy>=1.0.1 in /lustre06/project/6086105/ymbahram/gputorch3_10/lib/python3.10/site-packages (from matplotlib->improved-diffusion==0.0.0) (1.2.1+computecanada)
Requirement already satisfied: cycler>=0.10 in /lustre06/project/6086105/ymbahram/gputorch3_10/lib/python3.10/site-packages (from matplotlib->improved-diffusion==0.0.0) (0.12.1+computecanada)
Requirement already satisfied: pyparsing>=2.3.1 in /lustre06/project/6086105/ymbahram/gputorch3_10/lib/python3.10/site-packages (from matplotlib->improved-diffusion==0.0.0) (3.1.2+computecanada)
Requirement already satisfied: pillow>=8 in /lustre06/project/6086105/ymbahram/gputorch3_10/lib/python3.10/site-packages (from matplotlib->improved-diffusion==0.0.0) (10.3.0+computecanada)
Requirement already satisfied: kiwisolver>=1.3.1 in /lustre06/project/6086105/ymbahram/gputorch3_10/lib/python3.10/site-packages (from matplotlib->improved-diffusion==0.0.0) (1.4.5+computecanada)
Requirement already satisfied: python-dateutil>=2.7 in /lustre06/project/6086105/ymbahram/gputorch3_10/lib/python3.10/site-packages (from matplotlib->improved-diffusion==0.0.0) (2.9.0.post0+computecanada)
Requirement already satisfied: packaging>=20.0 in /lustre06/project/6086105/ymbahram/gputorch3_10/lib/python3.10/site-packages (from matplotlib->improved-diffusion==0.0.0) (24.1+computecanada)
WARNING: Retrying (Retry(total=4, connect=None, read=None, redirect=None, status=None)) after connection broken by 'NewConnectionError('<pip._vendor.urllib3.connection.HTTPSConnection object at 0x15517780fd30>: Failed to establish a new connection: [Errno 101] Network is unreachable')': /simple/keras/
WARNING: Retrying (Retry(total=3, connect=None, read=None, redirect=None, status=None)) after connection broken by 'NewConnectionError('<pip._vendor.urllib3.connection.HTTPSConnection object at 0x15517780f370>: Failed to establish a new connection: [Errno 101] Network is unreachable')': /simple/keras/
WARNING: Retrying (Retry(total=2, connect=None, read=None, redirect=None, status=None)) after connection broken by 'NewConnectionError('<pip._vendor.urllib3.connection.HTTPSConnection object at 0x15517780e890>: Failed to establish a new connection: [Errno 101] Network is unreachable')': /simple/keras/
WARNING: Retrying (Retry(total=1, connect=None, read=None, redirect=None, status=None)) after connection broken by 'NewConnectionError('<pip._vendor.urllib3.connection.HTTPSConnection object at 0x15517780e6b0>: Failed to establish a new connection: [Errno 101] Network is unreachable')': /simple/keras/
WARNING: Retrying (Retry(total=0, connect=None, read=None, redirect=None, status=None)) after connection broken by 'NewConnectionError('<pip._vendor.urllib3.connection.HTTPSConnection object at 0x15517780d3f0>: Failed to establish a new connection: [Errno 101] Network is unreachable')': /simple/keras/
Processing /cvmfs/soft.computecanada.ca/custom/python/wheelhouse/generic/keras-3.5.0+computecanada-py3-none-any.whl
Requirement already satisfied: setuptools in /lustre06/project/6086105/ymbahram/gputorch3_10/lib/python3.10/site-packages (from tensorflow->improved-diffusion==0.0.0) (65.5.0)
Requirement already satisfied: requests<3,>=2.21.0 in /lustre06/project/6086105/ymbahram/gputorch3_10/lib/python3.10/site-packages (from tensorflow->improved-diffusion==0.0.0) (2.32.3+computecanada)
WARNING: Retrying (Retry(total=4, connect=None, read=None, redirect=None, status=None)) after connection broken by 'NewConnectionError('<pip._vendor.urllib3.connection.HTTPSConnection object at 0x1551778244c0>: Failed to establish a new connection: [Errno 101] Network is unreachable')': /simple/gast/
WARNING: Retrying (Retry(total=3, connect=None, read=None, redirect=None, status=None)) after connection broken by 'NewConnectionError('<pip._vendor.urllib3.connection.HTTPSConnection object at 0x1551778248e0>: Failed to establish a new connection: [Errno 101] Network is unreachable')': /simple/gast/
WARNING: Retrying (Retry(total=2, connect=None, read=None, redirect=None, status=None)) after connection broken by 'NewConnectionError('<pip._vendor.urllib3.connection.HTTPSConnection object at 0x15517780cbe0>: Failed to establish a new connection: [Errno 101] Network is unreachable')': /simple/gast/
WARNING: Retrying (Retry(total=1, connect=None, read=None, redirect=None, status=None)) after connection broken by 'NewConnectionError('<pip._vendor.urllib3.connection.HTTPSConnection object at 0x15517780e5f0>: Failed to establish a new connection: [Errno 101] Network is unreachable')': /simple/gast/
WARNING: Retrying (Retry(total=0, connect=None, read=None, redirect=None, status=None)) after connection broken by 'NewConnectionError('<pip._vendor.urllib3.connection.HTTPSConnection object at 0x15517780dea0>: Failed to establish a new connection: [Errno 101] Network is unreachable')': /simple/gast/
Processing /cvmfs/soft.computecanada.ca/custom/python/wheelhouse/generic/gast-0.6.0+computecanada-py3-none-any.whl
slurmstepd: error: *** JOB 38085301 ON ng11103 CANCELLED AT 2024-12-07T00:04:54 DUE TO TIME LIMIT ***
