
The following have been reloaded with a version change:
  1) python/3.10.13 => python/3.11.5

/localscratch/spool/slurmd/job37375623/slurm_script: line 12: /home/ymbahram/projects/def-hadi87/ymbahram/gputorch/bin/activate: No such file or directory
Defaulting to user installation because normal site-packages is not writeable
Looking in links: /cvmfs/soft.computecanada.ca/custom/python/wheelhouse/gentoo2023/x86-64-v3, /cvmfs/soft.computecanada.ca/custom/python/wheelhouse/gentoo2023/generic, /cvmfs/soft.computecanada.ca/custom/python/wheelhouse/generic
Obtaining file:///lustre06/project/6086105/ymbahram/improved-diffusion/improved_diffusion/SDFT
  Preparing metadata (setup.py): started
  Preparing metadata (setup.py): finished with status 'done'
WARNING: Retrying (Retry(total=4, connect=None, read=None, redirect=None, status=None)) after connection broken by 'NewConnectionError('<pip._vendor.urllib3.connection.HTTPSConnection object at 0x14c0eeb191d0>: Failed to establish a new connection: [Errno 101] Network is unreachable')': /simple/blobfile/
WARNING: Retrying (Retry(total=3, connect=None, read=None, redirect=None, status=None)) after connection broken by 'NewConnectionError('<pip._vendor.urllib3.connection.HTTPSConnection object at 0x14c0ed229750>: Failed to establish a new connection: [Errno 101] Network is unreachable')': /simple/blobfile/
WARNING: Retrying (Retry(total=2, connect=None, read=None, redirect=None, status=None)) after connection broken by 'NewConnectionError('<pip._vendor.urllib3.connection.HTTPSConnection object at 0x14c0ed229f50>: Failed to establish a new connection: [Errno 101] Network is unreachable')': /simple/blobfile/
WARNING: Retrying (Retry(total=1, connect=None, read=None, redirect=None, status=None)) after connection broken by 'NewConnectionError('<pip._vendor.urllib3.connection.HTTPSConnection object at 0x14c0ed22a8d0>: Failed to establish a new connection: [Errno 101] Network is unreachable')': /simple/blobfile/
WARNING: Retrying (Retry(total=0, connect=None, read=None, redirect=None, status=None)) after connection broken by 'NewConnectionError('<pip._vendor.urllib3.connection.HTTPSConnection object at 0x14c0ed22b190>: Failed to establish a new connection: [Errno 101] Network is unreachable')': /simple/blobfile/
Processing /cvmfs/soft.computecanada.ca/custom/python/wheelhouse/generic/blobfile-2.1.1+computecanada-py3-none-any.whl (from improved-diffusion==0.0.0)
WARNING: Retrying (Retry(total=4, connect=None, read=None, redirect=None, status=None)) after connection broken by 'NewConnectionError('<pip._vendor.urllib3.connection.HTTPSConnection object at 0x14c0ec733710>: Failed to establish a new connection: [Errno 101] Network is unreachable')': /simple/torch/
WARNING: Retrying (Retry(total=3, connect=None, read=None, redirect=None, status=None)) after connection broken by 'NewConnectionError('<pip._vendor.urllib3.connection.HTTPSConnection object at 0x14c0ec733f90>: Failed to establish a new connection: [Errno 101] Network is unreachable')': /simple/torch/
WARNING: Retrying (Retry(total=2, connect=None, read=None, redirect=None, status=None)) after connection broken by 'NewConnectionError('<pip._vendor.urllib3.connection.HTTPSConnection object at 0x14c0ec748890>: Failed to establish a new connection: [Errno 101] Network is unreachable')': /simple/torch/
slurmstepd: error: *** JOB 37375623 ON ng30604 CANCELLED AT 2024-11-27T01:09:24 ***
